Workbook

Sheet Read me
B2: Australia dataset, for checking
B3: 45 programmes across the 8 Group of Eight universities, plus a 23 step student visa chain. Everything was web-checked on 13 September 2026 and every record already carries a source link and a quote from the page.
B6: What to do | C6: Work down the 'Check first' tab. It is sorted so the things that are visibly wrong on the site come before the things that are merely thin. Tick the Done column as you go and the counter at the top updates itself.
B8: Red rows | C8: Wrong on the page right now. Eight records. Half an hour.
B9: Amber rows | C9: Fields Germany fills on every record and Australia fills on none. They are answered once per university on the Institutions tab, not once per programme, so it is 8 cities and 8 homepages rather than 90 cells.
B10: Blue rows | C10: Judgement calls. Each is defensible as it stands. Read the ask column and decide.
B12: Already clean | C12: No stray line breaks, no double spaces, no smart quotes, no placeholder text, no duplicate programmes, no gaps in the record numbering, and every one of the 45 records has a quote of 67 characters or more. None of that needs re-checking.
B14: On the links | C14: Automated checking cannot confirm these. Melbourne, Monash and UQ block scripted requests, which is why 30 of the 90 URLs answered 403 or timed out to a robot. That is the university's bot filter, not a dead link. Opening them in a browser is the only check that means anything, which is what the 'Link never marked as opening' rows are for.
B16: On coverage | C16: Every record here is Group of Eight. That is a deliberate top end rather than a cross-section: no Australian Technology Network, no regional universities, and Adelaide University is included post-merger. Worth deciding whether the file claims to cover Australia or to cover the Go8.
B18: Sending edits back | C18: Edit in place on the Programmes tab. Keep the record_id column untouched, since that is what the import matches on.

Sheet Check first
A1: Done | B1: Of | D1: Red open / amber open / blue open
A2: =COUNTIF(A4:A113,"yes") | B2: =COUNTA(C4:C113) | D2: =COUNTIFS(B4:B113,1,A4:A113,"")&" red, "&COUNTIFS(B4:B113,2,A4:A113,"")&" amber, "&COUNTIFS(B4:B113,3,A4:A113,"")&" blue"
A3: Done | B3: Priority | C3: Record | D3: What is wrong | E3: Field | F3: What it says now | G3: What to do
B4: 1 | C4: AU-040 | D4: Degree name carries a comment | E4: degree | F4: Bachelor (Honours) — now titled Bachelor of Laws (Honours) | G4: Set it to 'Bachelor of Laws (Honours)' and move the rename into notes
B5: 1 | C5: AU-037 | D5: Institution name carries an editorial note, and that note is what the reader sees | E5: institution | F5: Adelaide University (merged University of Adelaide + UniSA; sheet listed University of Adelaide) | G5: Set the name to 'Adelaide University'. The merger belongs in notes, where it already is
B6: 1 | C6: AU-038 | D6: Institution name carries an editorial note, and that note is what the reader sees | E6: institution | F6: Adelaide University (merged University of Adelaide + UniSA; sheet listed University of Adelaide) | G6: Set the name to 'Adelaide University'. The merger belongs in notes, where it already is
B7: 1 | C7: AU-039 | D7: Institution name carries an editorial note, and that note is what the reader sees | E7: institution | F7: Adelaide University (merged University of Adelaide + UniSA; sheet listed University of Adelaide) | G7: Set the name to 'Adelaide University'. The merger belongs in notes, where it already is
B8: 1 | C8: AU-040 | D8: Institution name carries an editorial note, and that note is what the reader sees | E8: institution | F8: Adelaide University (merged University of Adelaide + UniSA; sheet listed University of Adelaide) | G8: Set the name to 'Adelaide University'. The merger belongs in notes, where it already is
B9: 1 | C9: AU-041 | D9: Institution name carries an editorial note, and that note is what the reader sees | E9: institution | F9: Adelaide University (merged University of Adelaide + UniSA; sheet listed University of Adelaide) | G9: Set the name to 'Adelaide University'. The merger belongs in notes, where it already is
B10: 1 | C10: AU-031 | D10: Source link has words after the URL, so it does not open | E10: source_url_you_used | F10: https://study.uq.edu.au/study-options/programs/bachelor-commerce-2336 (entry-requirements selector, S1 2027, India) | G10: Move everything after the URL into notes, leave the bare link
B11: 1 | C11: AU-032 | D11: Source link has words after the URL, so it does not open | E11: source_url_you_used | F11: https://study.uq.edu.au/study-options/programs/bachelor-business-management-2171 (entry-requirements selector, S1 2027, India) | G11: Move everything after the URL into notes, leave the bare link
B12: 1 | C12: AU-033 | D12: Source link has words after the URL, so it does not open | E12: source_url_you_used | F12: https://study.uq.edu.au/study-options/programs/bachelor-engineering-honours-2455 (entry-requirements selector, S1 2027, India) | G12: Move everything after the URL into notes, leave the bare link
B13: 1 | C13: AU-034 | D13: Source link has words after the URL, so it does not open | E13: source_url_you_used | F13: https://study.uq.edu.au/study-options/programs/bachelor-science-2461 (entry-requirements selector, S1 2027, India) | G13: Move everything after the URL into notes, leave the bare link
B14: 1 | C14: AU-035 | D14: Source link has words after the URL, so it does not open | E14: source_url_you_used | F14: https://study.uq.edu.au/study-options/programs/bachelor-laws-honours-2471 (entry-requirements selector, S1 2027, India) | G14: Move everything after the URL into notes, leave the bare link
B15: 1 | C15: AU-036 | D15: Source link has words after the URL, so it does not open | E15: source_url_you_used | F15: https://study.uq.edu.au/study-options/programs/bachelor-advanced-finance-and-economics-honours-2140 (entry-requirements selector, S1 2027, India) | G15: Move everything after the URL into notes, leave the bare link
... B113: 3 | C113: AU-036 | D113: Sortable deadline names a year the source sentence does not | E113: deadline_iso | F113: 2026-11-30 <- Semester 1 only: applications close 30 November of the previous year | G113: Confirm the year. The source says 'the year prior to commencement' without naming one

Sheet Programmes
A1: record_id (do not edit) | B1: institution | C1: city | D1: programme | E1: degree | F1: url | G1: institution type | H1: language | I1: years | J1: entry | K1: IB | L1: A Level | M1: CBSE | N1: ISC | O1: other | P1: English requirement | Q1: selection | R1: deadline | S1: tuition, international | T1: scholarships | U1: visa | V1: apply | W1: notes | X1: status | Y1: what the sheet got wrong | Z1: source URL | AA1: exact quote | AB1: date checked | AC1: link works | AD1: checked by | AE1: documents required | AF1: deadline rounds | AG1: fee year | AH1: application fee | AI1: deadline (sortable) | AJ1: India entry (combined)
A2: AU-001 | B2: University of Melbourne | C2: Australia | D2: Bachelor of Commerce | E2: Bachelor | F2: https://study.unimelb.edu.au/find/courses/undergraduate/bachelor-of-commerce/ | G2: Go8 / Top Research | H2: English | I2: 3 | J2: Only Tamil Nadu HSC, Maharashtra HSC and Karnataka PUC accepted as direct-entry Indian state boards | K2: 35 (2026 entry score, guide only). Prerequisites: grade 4 in an approved English subject and grade 4 in Mathematics Analysis & Approaches (SL or HL) or grade 4 in Mathematics Applications & Interpretation HL (AI SL not accepted) | L2: ABB (2026 entry score, guide only). Prerequisites: Mathematics and an approved A/AS Level English subject; minimum three A Levels, grade C or better in prerequisite subjects | M2: 81.00 (2026 entry score, guide only) - average of best four final-year subjects; prerequisites English and Mathematics | N2: 81.00 (2026 entry score, guide only) - average of best four final-year subjects; prerequisites English and Mathematics | O2: Academic merit against published entry score; meeting minimum entry and English requirements does not guarantee selection. July-start Actuarial Studies majors need higher maths (Calculus 2 entry level) | P2: IELTS 6.5 overall with no band less than 6.0 (course page header, international view) | Q2: None | R2: Direct international applications close: mid-year intake 2026 (Semester 2/July) 31 May 2026; start-year intake 2027 (Semester 1/February-March) 30 November 2026; mid-year 2027 31 May 2027 | S2: AUD 52,360 - 59,052 indicative first year fee (2026); AUD 56,451 - 62,464 (2027). Fees are subject-based (discipline fee bands) | T2: Melbourne International Undergraduate Scholarship and Melbourne Chancellor's Scholarship (automatically considered on application); A.G. Whitlam International Undergraduate Merit Scholarship (Bangladesh, India, Sri Lanka, Vietnam); International Undergraduate Partner Scholarship; Bachelor of Commerce Global Scholarship; Commerce Achievement Scholarship | U2: Australian Student visa (subclass 500) after accepting offer and receiving CoE; OSHC compulsory; full-time enrolment in CRICOS-registered course required; Genuine Student requirement applies | V2: Direct online application via the University of Melbourne application portal for both intakes; VTAC for start-year intake if completing an Australian Year 12 (anywhere) or the IB in Australia/NZ; applicants from certain countries must apply through an authorised education agent | W2: CRICOS 002143B. Intakes: March (Semester 1) and July (Semester 2) for internationals. Seven majors incl. Accounting, Actuarial Studies, Finance. AUD 17,000 deposit payable on acceptance. | X2: Confirmed | Y2: Sheet CBSE 88%+ and ISC 80%+ vs published 81.00 for both; sheet IB band 34-38 vs published 2026 guide score 35; sheet deadline 'May 31' is only the mid-year close - Semester 1 direct applications close 30 November; sheet A-level ABB matches | Z2: https://study.unimelb.edu.au/find/courses/undergraduate/bachelor-of-commerce/fees/ | AA2: 2026 fees Indicative first year fee AUD$52,360 - $59,052 [...] CRICOS code: 002143B | AB2: 13 September 2026 | AC2: yes | AD2: Pave verification, web-checked | AE2: Academic transcripts/certificates, evidence of English language proficiency, passport identity page; applicants who studied in certain countries must apply via an authorised agent for document verification | AF2: Deadlines published for 2026 mid-year and both 2027 intakes as of 13 September 2026 (study.unimelb.edu.au/how-to-apply/undergraduate-study/international-applications/applications) | AG2: 2026 (2027 also published) | AH2: AUD 154 non-refundable per direct international application (exemptions apply, e.g. sponsored applicants) | AI2: 2026-11-30 | AJ2: 81.00 (2026 entry score, guide only) - average of best four final-year subjects; prerequisites English and Mathematics | ISC: 81.00 (2026 entry score, guide only) - average of best four final-year subjects; prerequisites English and Mathematics
A3: AU-002 | B3: University of Melbourne | C3: Australia | D3: Bachelor of Science | E3: Bachelor | F3: https://study.unimelb.edu.au/find/courses/undergraduate/bachelor-of-science/ | G3: Go8 / Top Research | H3: English | I3: 3 | J3: Only Tamil Nadu HSC, Maharashtra HSC and Karnataka PUC accepted as direct-entry Indian state boards | K3: 31 (2026 entry score, guide only). Prerequisites: grade 4 in English/English B, grade 4 in Mathematics (AI HL, AA SL or AA HL), and grade 4 in one of Biology, Chemistry or Physics (HL or SL) | L3: BBB (2026 entry score, guide only). Prerequisites: Mathematics, one of Biology/Chemistry/Physics, and an approved A/AS Level English subject (or Maths + Further Maths + English); min. three A Levels, grade C in prerequisites | M3: 75.00 (2026 entry score, guide only) - average of best four final-year subjects; prerequisites English, Mathematics and one of Biology/Chemistry/Physics | N3: 75.00 (2026 entry score, guide only) - same basis as CBSE | O3: Academic merit against published entry score; subject prerequisites must be met with stated minimum grades | P3: IELTS 6.5 overall with no band less than 6.0 (course page header, international view) | Q3: None | R3: Direct international applications close: mid-year intake 2026 (Semester 2/July) 31 May 2026; start-year intake 2027 (Semester 1/February-March) 30 November 2026; mid-year 2027 31 May 2027 | S3: AUD 52,944 - 62,208 indicative first year fee (2026); AUD 55,556 - 65,344 (2027) | T3: Melbourne International Undergraduate Scholarship and Melbourne Chancellor's Scholarship (automatically considered on application); A.G. Whitlam International Undergraduate Merit Scholarship (Bangladesh, India, Sri Lanka, Vietnam); International Undergraduate Partner Scholarship | U3: Australian Student visa (subclass 500) after accepting offer and receiving CoE; OSHC compulsory; full-time enrolment in CRICOS-registered course required; Genuine Student requirement applies | V3: Direct online application via the University of Melbourne application portal for both intakes; VTAC for start-year intake if completing an Australian Year 12 (anywhere) or the IB in Australia/NZ; applicants from certain countries must apply through an authorised education agent | W3: CRICOS 002153M. Intakes: March and July. 40+ majors incl. computing, mathematics, psychology; gateway to graduate engineering/medicine. | X3: Confirmed | Y3: Sheet IB 32-36 vs published 31; sheet CBSE 85%+ vs 75.00; sheet ISC 78%+ vs 75.00; sheet fee AUD 52,944 matches published lower bound | Z3: https://study.unimelb.edu.au/find/courses/undergraduate/bachelor-of-science/fees/ | AA3: 2026 fees Indicative first year fee AUD$52,944 - $62,208 [...] CRICOS code: 002153M | AB3: 13 September 2026 | AC3: yes | AD3: Pave verification, web-checked | AE3: Academic transcripts/certificates, evidence of English language proficiency, passport identity page; applicants who studied in certain countries must apply via an authorised agent for document verification | AF3: Deadlines published for 2026 mid-year and both 2027 intakes as of 13 September 2026 (study.unimelb.edu.au/how-to-apply/undergraduate-study/international-applications/applications) | AG3: 2026 (2027 also published) | AH3: AUD 154 non-refundable per direct international application (exemptions apply, e.g. sponsored applicants) | AI3: 2026-11-30 | AJ3: 75.00 (2026 entry score, guide only) - average of best four final-year subjects; prerequisites English, Mathematics and one of Biology/Chemistry/Physics | ISC: 75.00 (2026 entry score, guide only) - same basis as CBSE
A4: AU-003 | B4: University of Melbourne | C4: Australia | D4: Bachelor of Arts | E4: Bachelor | F4: https://study.unimelb.edu.au/find/courses/undergraduate/bachelor-of-arts/ | G4: Go8 / Top Research | H4: English | I4: 3 | J4: Only Tamil Nadu HSC, Maharashtra HSC and Karnataka PUC accepted as direct-entry Indian state boards | K4: 30 (2026 entry score, guide only). Prerequisite: grade 4 in English or English B (SL or HL) | L4: BBB (2026 entry score, guide only). Prerequisite: an approved A/AS Level English subject; Economics majors strongly encouraged to take Mathematics; min. three A Levels | M4: 65.00 (2026 entry score, guide only) - average of best four final-year subjects; prerequisite English | N4: 65.00 (2026 entry score, guide only) - same basis as CBSE | O4: Academic merit against published entry score | P4: IELTS 6.5 overall with no band less than 6.0 (course page header, international view) | Q4: None | R4: Direct international applications close: mid-year intake 2026 (Semester 2/July) 31 May 2026; start-year intake 2027 (Semester 1/February-March) 30 November 2026; mid-year 2027 31 May 2027 | S4: AUD 38,004 - 56,252 indicative first year fee (2026); AUD 44,356 - 57,764 (2027) | T4: Melbourne International Undergraduate Scholarship and Melbourne Chancellor's Scholarship (automatically considered on application); A.G. Whitlam International Undergraduate Merit Scholarship (Bangladesh, India, Sri Lanka, Vietnam); International Undergraduate Partner Scholarship | U4: Australian Student visa (subclass 500) after accepting offer and receiving CoE; OSHC compulsory; full-time enrolment in CRICOS-registered course required; Genuine Student requirement applies | V4: Direct online application via the University of Melbourne application portal for both intakes; VTAC for start-year intake if completing an Australian Year 12 (anywhere) or the IB in Australia/NZ; applicants from certain countries must apply through an authorised education agent | W4: CRICOS 002167E. Intakes: March and July. 40+ majors across humanities and social sciences. | X4: Confirmed | Y4: Sheet A-level BBC vs published BBB; sheet CBSE 83%+ vs 65.00; sheet ISC 75%+ vs 65.00; sheet IB lower bound 30 matches published 30 | Z4: https://study.unimelb.edu.au/find/courses/undergraduate/bachelor-of-arts/fees/ | AA4: 2026 fees Indicative first year fee AUD$38,004 - $56,252 [...] CRICOS code: 002167E | AB4: 13 September 2026 | AC4: yes | AD4: Pave verification, web-checked | AE4: Academic transcripts/certificates, evidence of English language proficiency, passport identity page; applicants who studied in certain countries must apply via an authorised agent for document verification | AF4: Deadlines published for 2026 mid-year and both 2027 intakes as of 13 September 2026 (study.unimelb.edu.au/how-to-apply/undergraduate-study/international-applications/applications) | AG4: 2026 (2027 also published) | AH4: AUD 154 non-refundable per direct international application (exemptions apply, e.g. sponsored applicants) | AI4: 2026-11-30 | AJ4: 65.00 (2026 entry score, guide only) - average of best four final-year subjects; prerequisite English | ISC: 65.00 (2026 entry score, guide only) - same basis as CBSE
A5: AU-004 | B5: University of Melbourne | C5: Australia | D5: Bachelor of Design | E5: Bachelor | F5: https://study.unimelb.edu.au/find/courses/undergraduate/bachelor-of-design/ | G5: Go8 / Top Research | H5: English | I5: 3 | J5: Mathematical knowledge equivalent to VCE Mathematical Methods (study score 25+) required for Construction, Civil/Mechanical/Digital-Infrastructure Systems and Computing majors; any VCE Mathematics for Property major | K5: 30 (2026 entry score, guide only). Prerequisite: grade 4 in English or English B (SL or HL) | L5: BBB (2026 entry score, guide only). Prerequisite: an approved A/AS Level English subject; min. three A Levels | M5: 70.00 (2026 entry score, guide only) - average of best four final-year subjects | N5: 70.00 (2026 entry score, guide only) - same basis as CBSE | O5: Academic merit against published entry score; major-specific maths knowledge requirements | P5: IELTS 6.5 overall with no band less than 6.0 (course page header, international view) | Q5: None - entry is score-based; no portfolio required for admission | R5: Direct international applications close: mid-year intake 2026 (Semester 2/July) 31 May 2026; start-year intake 2027 (Semester 1/February-March) 30 November 2026; mid-year 2027 31 May 2027 | S5: AUD 43,868 - 57,900 indicative first year fee (2026); AUD 45,928 - 63,924 (2027) | T5: Melbourne International Undergraduate Scholarship and Melbourne Chancellor's Scholarship (automatically considered on application); A.G. Whitlam International Undergraduate Merit Scholarship (Bangladesh, India, Sri Lanka, Vietnam); International Undergraduate Partner Scholarship | U5: Australian Student visa (subclass 500) after accepting offer and receiving CoE; OSHC compulsory; full-time enrolment in CRICOS-registered course required; Genuine Student requirement applies | V5: Direct online application via the University of Melbourne application portal for both intakes; VTAC for start-year intake if completing an Australian Year 12 (anywhere) or the IB in Australia/NZ; applicants from certain countries must apply through an authorised education agent | W5: CRICOS 090744C. Intakes: March and July. Majors incl. architecture, landscape architecture, urban planning, construction, engineering systems. | X5: Confirmed | Y5: Sheet fee 'AUD 50,000-56,000' vs published AUD 43,868-57,900 (2026); sheet A-level BBC vs BBB; sheet CBSE 80%+ vs 70.00; sheet ISC 73%+ vs 70.00 | Z5: https://study.unimelb.edu.au/find/courses/undergraduate/bachelor-of-design/fees/ | AA5: 2026 fees Indicative first year fee AUD$43,868 - $57,900 [...] CRICOS code: 090744C | AB5: 13 September 2026 | AC5: yes | AD5: Pave verification, web-checked | AE5: Academic transcripts/certificates, evidence of English language proficiency, passport identity page; applicants who studied in certain countries must apply via an authorised agent for document verification | AF5: Deadlines published for 2026 mid-year and both 2027 intakes as of 13 September 2026 (study.unimelb.edu.au/how-to-apply/undergraduate-study/international-applications/applications) | AG5: 2026 (2027 also published) | AH5: AUD 154 non-refundable per direct international application (exemptions apply, e.g. sponsored applicants) | AI5: 2026-11-30 | AJ5: 70.00 (2026 entry score, guide only) - average of best four final-year subjects | ISC: 70.00 (2026 entry score, guide only) - same basis as CBSE
A6: AU-005 | B6: University of Melbourne | C6: Australia | D6: Bachelor of Biomedicine | E6: Bachelor | F6: https://study.unimelb.edu.au/find/courses/undergraduate/bachelor-of-biomedicine/ | G6: Go8 / Top Research | H6: English | I6: 3 | J6: Only Tamil Nadu HSC, Maharashtra HSC and Karnataka PUC accepted as direct-entry Indian state boards | K6: 35 (2026 entry score, guide only). Prerequisites: grade 4 in English/English B, grade 4 in Chemistry, grade 4 in Mathematics (AI HL, AA SL or AA HL) | L6: AAB (2026 entry score, guide only). Prerequisites: Chemistry, Mathematics and an approved A/AS Level English subject; min. three A Levels, grade C in prerequisites | M6: 91.00 (2026 entry score, guide only) - average of best four final-year subjects; prerequisites English, Chemistry and Mathematics | N6: 91.00 (2026 entry score, guide only) - same basis as CBSE | O6: Academic merit against published entry score; subject prerequisites (Chemistry + Mathematics + English) strictly applied | P6: IELTS 6.5 overall with no band less than 6.0 (course page header, international view) | Q6: None for the bachelor (graduate Doctor of Medicine entry later requires separate selection) | R6: Direct international applications close: mid-year intake 2026 (Semester 2/July) 31 May 2026; start-year intake 2027 (Semester 1/February-March) 30 November 2026; mid-year 2027 31 May 2027 | S6: AUD 54,780 - 61,460 indicative first year fee (2026); AUD 58,084 - 65,288 (2027) | T6: Melbourne International Undergraduate Scholarship and Melbourne Chancellor's Scholarship (automatically considered on application); A.G. Whitlam International Undergraduate Merit Scholarship (Bangladesh, India, Sri Lanka, Vietnam); International Undergraduate Partner Scholarship | U6: Australian Student visa (subclass 500) after accepting offer and receiving CoE; OSHC compulsory; full-time enrolment in CRICOS-registered course required; Genuine Student requirement applies | V6: Direct online application via the University of Melbourne application portal for both intakes; VTAC for start-year intake if completing an Australian Year 12 (anywhere) or the IB in Australia/NZ; applicants from certain countries must apply through an authorised education agent | W6: CRICOS 058838G. Intakes: March and July. Pathway toward graduate Doctor of Medicine (separate selection). | X6: Confirmed | Y6: Sheet IB 39-43 vs published 2026 guide score 35; sheet A-level AAA vs AAB; sheet CBSE 95%+ vs 91.00; sheet ISC 90%+ vs 91.00; sheet fee 52,000-60,000 vs published 54,780-61,460 | Z6: https://study.unimelb.edu.au/find/courses/undergraduate/bachelor-of-biomedicine/fees/ | AA6: 2026 fees Indicative first year fee AUD$54,780 - $61,460 [...] CRICOS code: 058838G | AB6: 13 September 2026 | AC6: yes | AD6: Pave verification, web-checked | AE6: Academic transcripts/certificates, evidence of English language proficiency, passport identity page; applicants who studied in certain countries must apply via an authorised agent for document verification | AF6: Deadlines published for 2026 mid-year and both 2027 intakes as of 13 September 2026 (study.unimelb.edu.au/how-to-apply/undergraduate-study/international-applications/applications) | AG6: 2026 (2027 also published) | AH6: AUD 154 non-refundable per direct international application (exemptions apply, e.g. sponsored applicants) | AI6: 2026-11-30 | AJ6: 91.00 (2026 entry score, guide only) - average of best four final-year subjects; prerequisites English, Chemistry and Mathematics | ISC: 91.00 (2026 entry score, guide only) - same basis as CBSE
A7: AU-006 | B7: University of Melbourne | C7: Australia | D7: Bachelor of Music | E7: Bachelor | F7: https://study.unimelb.edu.au/find/courses/undergraduate/bachelor-of-music-performance/ | G7: Go8 / Top Research | H7: English | I7: 3 | K7: No entry score published - 'Range of criteria used for selection' (audition-based). Prerequisite: grade 4 in English or English B (SL or HL) | L7: No entry score published - selection is audition/talent-based; approved A/AS Level English subject required | M7: No cutoff published - selection is audition-based; English prerequisite; best-four average basis applies for the academic component | N7: No cutoff published - selection is audition-based; English prerequisite | O7: Talent-based selection via audition; academic prerequisites (English) must also be met | P7: IELTS 6.5 overall with no band less than 6.0 (course page header, international view) | Q7: Audition required ('Selection into the Bachelor of Music (Performance) is talent-based. Applicants are required to complete an audition.') | R7: Direct international applications close: mid-year intake 2026 (Semester 2/July) 31 May 2026; start-year intake 2027 (Semester 1/February-March) 30 November 2026; mid-year 2027 31 May 2027; audition/supplementary-task courses close earlier via VTAC (before September) | S7: AUD 39,936 - 44,213 indicative first year fee (2026) for Bachelor of Music (Performance) | T7: Melbourne International Undergraduate Scholarship and Melbourne Chancellor's Scholarship (automatically considered on application); A.G. Whitlam International Undergraduate Merit Scholarship (Bangladesh, India, Sri Lanka, Vietnam); International Undergraduate Partner Scholarship | U7: Australian Student visa (subclass 500) after accepting offer and receiving CoE; OSHC compulsory; full-time enrolment in CRICOS-registered course required; Genuine Student requirement applies | V7: Direct online application via the University of Melbourne application portal for both intakes; VTAC for start-year intake if completing an Australian Year 12 (anywhere) or the IB in Australia/NZ; applicants from certain countries must apply through an authorised education agent. VTAC applications for degrees requiring auditions (incl. Music) close before September each year | W7: CRICOS 058837J (Performance stream). February (Semester 1) intake only; Southbank campus. The generic 'Bachelor of Music' URL in the source sheet is dead: Melbourne now lists separate stream degrees - Performance, Composition, Interactive Composition, Music Studies, Musicology & Ethnomusicology; data here is for the Performance stream. | X7: Confirmed | Y7: Source course_url (bachelor-of-music) is dead - course restructured into stream-specific degrees; sheet IB 29 / CBSE 80%+ / ISC 73%+ / A-level 'BB+' have no published basis (no entry scores published - audition-based); sheet fee 42,000-48,000 vs published 39,936-44,213 (Performance); sheet intake 'May 31 deadline' not applicable as stated | Z7: https://study.unimelb.edu.au/find/courses/undergraduate/bachelor-of-music-performance/fees/ | AA7: Selection into the Bachelor of Music (Performance) is talent-based. Applicants are required to complete an audition. | AB7: 13 September 2026 | AC7: yes | AD7: Pave verification, web-checked | AE7: Academic transcripts/certificates, evidence of English language proficiency, passport identity page; applicants who studied in certain countries must apply via an authorised agent for document verification; audition (performance stream) | AF7: Course-specific audition deadlines not centrally published on the pages checked 13 September 2026 - confirm with the Melbourne Conservatorium | AG7: 2026 | AH7: AUD 154 non-refundable per direct international application (exemptions apply, e.g. sponsored applicants) | AJ7: No cutoff published - selection is audition-based; English prerequisite; best-four average basis applies for the academic component | ISC: No cutoff published - selection is audition-based; English prerequisite
A8: AU-007 | B8: University of Sydney | C8: Australia | D8: Bachelor of Commerce | E8: Bachelor | F8: https://www.sydney.edu.au/courses/courses/uc/bachelor-of-commerce.html | G8: Go8 / Top Research | H8: English | I8: 3 | J8: Indian State Board Higher Secondary School Certificate: 95 (2026); ATAR equivalent 96.0 | K8: 38 (2026 indicative entry score, international; 'All scores listed are a guide for admission and subject to change') | L8: 17 points from best 3 A2 subjects / 19 from best 4. A-level aggregate from A2 subjects, A*=6 A=5 B=4 C=3 D=2 E=1; first figure = 3 subjects, second = 4 subjects (AS not counted) | M8: 19.0 aggregate (2026 indicative entry score). CBSE aggregate basis: English or Hindi plus best four remaining externally examined subjects, graded A1=4, A2=3.5, B1=3, B2=2.5, C1=2, C2=1.5, D1=1, D2=0.5 (max 20; five A1s with 96+ exam average deemed 21) | N8: 94 (2026 indicative entry score). ISC basis: average of the best four subjects including English | O8: Rank-based admission on qualification entry score; scholarship rounds have separate deadlines | P8: IELTS: 'A minimum result of 7.0 overall and a minimum result of 6.0 in each band' (course-specific); TOEFL iBT 96 overall (R/L/S 17, W 19) | Q8: None. No prerequisites; assumed knowledge: Mathematics Standard or higher depending on majors | R8: International direct applications close 1 December of the year prior to commencement for Semester 1 (February) and 29 May of the commencing year for Semester 2 (August) | S8: A$56,300 international tuition fee for 2026 (first-year estimate, 48 credit points) | T8: Vice-Chancellor's International Scholarships Scheme (merit-based, assessed from the admission application); Sydney International Student Award | U8: Australian Student visa (subclass 500) after acceptance and CoE; OSHC required; available to student visa holders (course pages state 'Available to student visa holders') | V8: Three ways: apply directly to the University (online), via an authorised agent, or via UAC - UAC is mandatory if completing an Australian Year 12 (anywhere) or the IB in Australia | W8: CRICOS 012849G. Intakes: Semester 1 (February) and Semester 2 (August). 144 credit points. Business School triple accredited. | X8: Confirmed | Y8: Sheet IELTS 6.5/6.0 vs published 7.0 overall/6.0 bands; sheet fee 50,000 vs published 56,300; sheet CBSE '88%+' uses wrong metric (Sydney publishes a 20-point grade aggregate: 19.0); sheet ISC 80%+ vs 94; sheet deadline 'May 15' vs published 1 Dec (S1)/29 May (S2); sheet IB band 34-38: published figure is 38 | Z8: https://www.sydney.edu.au/courses/courses/uc/bachelor-of-commerce.html | AA8: IELTS score: A minimum result of 7.0 overall and a minimum result of 6.0 in each band; International Full Fee Paying Rate $56,300 (2026) | AB8: 13 September 2026 | AC8: yes | AD8: Pave verification, web-checked | AE8: Academic transcripts and completion certificates, English test evidence, passport; supplementary evidence via UAC where applicable | AF8: Standing university-wide closing dates published (sydney.edu.au/study/applying/application-dates.html), checked 13 September 2026; for 2027 Semester 1 that means 1 December 2026 | AG8: 2026 | AH8: A$150.00 non-refundable application processing fee (covers all applications made within one year); exemptions incl. full scholarship/sponsorship holders | AI8: 2026-12-01 | AJ8: 19.0 aggregate (2026 indicative entry score). CBSE aggregate basis: English or Hindi plus best four remaining externally examined subjects, graded A1=4, A2=3.5, B1=3, B2=2.5, C1=2, C2=1.5, D1=1, D2=0.5 (max 20; five A1s with 96+ exam average deemed 21) | ISC: 94 (2026 indicative entry score). ISC basis: average of the best four subjects including English
A9: AU-008 | B9: University of Sydney | C9: Australia | D9: Bachelor of Science | E9: Bachelor | F9: https://www.sydney.edu.au/courses/courses/uc/bachelor-of-science.html | G9: Go8 / Top Research | H9: English | I9: 3 | J9: ATAR equivalent 80.0 | K9: 29 (2026 indicative entry score, international) | L9: 13 points from best 3 A2 subjects / 13 from best 4. A-level aggregate from A2 subjects, A*=6 A=5 B=4 C=3 D=2 E=1; first figure = 3 subjects, second = 4 subjects (AS not counted) | M9: 14.0 aggregate (2026 indicative entry score). CBSE aggregate basis: English or Hindi plus best four remaining externally examined subjects, graded A1=4, A2=3.5, B1=3, B2=2.5, C1=2, C2=1.5, D1=1, D2=0.5 (max 20; five A1s with 96+ exam average deemed 21) | N9: 84 (2026 indicative entry score). ISC basis: average of the best four subjects including English | O9: Rank-based admission on qualification entry score | P9: IELTS: 'A minimum result of 6.5 overall and a minimum result of 6.0 in each band' | Q9: None. No prerequisites; assumed knowledge: Mathematics Advanced | R9: International direct applications close 1 December of the year prior to commencement for Semester 1 (February) and 29 May of the commencing year for Semester 2 (August) | S9: A$60,600 international tuition fee for 2026 (first-year estimate) | T9: Vice-Chancellor's International Scholarships Scheme (merit-based, assessed from the admission application); Sydney International Student Award | U9: Australian Student visa (subclass 500) after acceptance and CoE; OSHC required; available to student visa holders (course pages state 'Available to student visa holders') | V9: Three ways: apply directly to the University (online), via an authorised agent, or via UAC - UAC is mandatory if completing an Australian Year 12 (anywhere) or the IB in Australia | W9: CRICOS 000719E. Intakes: Semester 1 (February) and Semester 2 (August). 144 credit points. | X9: Confirmed | Y9: Sheet IB 32-36 vs published 29; sheet fee 49,000 vs 60,600; sheet CBSE '85%+' wrong metric (published 14.0/20 aggregate); sheet ISC 78%+ vs 84; sheet ATAR ~85 vs published 80.0; sheet deadline 15 May wrong | Z9: https://www.sydney.edu.au/courses/courses/uc/bachelor-of-science.html | AA9: IELTS score: A minimum result of 6.5 overall and a minimum result of 6.0 in each band; International Full Fee Paying Rate $60,600 (2026) | AB9: 13 September 2026 | AC9: yes | AD9: Pave verification, web-checked | AE9: Academic transcripts and completion certificates, English test evidence, passport; supplementary evidence via UAC where applicable | AF9: Standing university-wide closing dates published (sydney.edu.au/study/applying/application-dates.html), checked 13 September 2026; for 2027 Semester 1 that means 1 December 2026 | AG9: 2026 | AH9: A$150.00 non-refundable application processing fee (covers all applications made within one year); exemptions incl. full scholarship/sponsorship holders | AI9: 2026-12-01 | AJ9: 14.0 aggregate (2026 indicative entry score). CBSE aggregate basis: English or Hindi plus best four remaining externally examined subjects, graded A1=4, A2=3.5, B1=3, B2=2.5, C1=2, C2=1.5, D1=1, D2=0.5 (max 20; five A1s with 96+ exam average deemed 21) | ISC: 84 (2026 indicative entry score). ISC basis: average of the best four subjects including English
A10: AU-009 | B10: University of Sydney | C10: Australia | D10: Bachelor of Arts | E10: Bachelor | F10: https://www.sydney.edu.au/courses/courses/uc/bachelor-of-arts.html | G10: Go8 / Top Research | H10: English | I10: 3 | J10: ATAR equivalent 75.0 | K10: 26 (2026 indicative entry score, international) | L10: 12 points from best 3 A2 subjects / 12 from best 4. A-level aggregate from A2 subjects, A*=6 A=5 B=4 C=3 D=2 E=1; first figure = 3 subjects, second = 4 subjects (AS not counted) | M10: 12.5 aggregate (2026 indicative entry score). CBSE aggregate basis: English or Hindi plus best four remaining externally examined subjects, graded A1=4, A2=3.5, B1=3, B2=2.5, C1=2, C2=1.5, D1=1, D2=0.5 (max 20; five A1s with 96+ exam average deemed 21) | N10: 81 (2026 indicative entry score). ISC basis: average of the best four subjects including English | O10: Rank-based admission on qualification entry score | P10: IELTS: 'A minimum result of 6.5 overall and a minimum result of 6.0 in each band' | Q10: None. No prerequisites; assumed knowledge depends on majors chosen | R10: International direct applications close 1 December of the year prior to commencement for Semester 1 (February) and 29 May of the commencing year for Semester 2 (August) | S10: A$52,500 international tuition fee for 2026 (first-year estimate) | T10: Vice-Chancellor's International Scholarships Scheme (merit-based, assessed from the admission application); Sydney International Student Award | U10: Australian Student visa (subclass 500) after acceptance and CoE; OSHC required; available to student visa holders (course pages state 'Available to student visa holders') | V10: Three ways: apply directly to the University (online), via an authorised agent, or via UAC - UAC is mandatory if completing an Australian Year 12 (anywhere) or the IB in Australia | W10: CRICOS 000705M. Intakes: Semester 1 (February) and Semester 2 (August). 144 credit points, 40+ majors. | X10: Confirmed | Y10: Sheet IB 29-33 vs published 26; sheet fee 45,000 vs 52,500; sheet CBSE '82%+' wrong metric (published 12.5/20 aggregate); sheet ISC 75%+ vs 81; sheet deadline 15 May wrong | Z10: https://www.sydney.edu.au/courses/courses/uc/bachelor-of-arts.html | AA10: IELTS score: A minimum result of 6.5 overall and a minimum result of 6.0 in each band; International Full Fee Paying Rate $52,500 (2026) | AB10: 13 September 2026 | AC10: yes | AD10: Pave verification, web-checked | AE10: Academic transcripts and completion certificates, English test evidence, passport; supplementary evidence via UAC where applicable | AF10: Standing university-wide closing dates published (sydney.edu.au/study/applying/application-dates.html), checked 13 September 2026; for 2027 Semester 1 that means 1 December 2026 | AG10: 2026 | AH10: A$150.00 non-refundable application processing fee (covers all applications made within one year); exemptions incl. full scholarship/sponsorship holders | AI10: 2026-12-01 | AJ10: 12.5 aggregate (2026 indicative entry score). CBSE aggregate basis: English or Hindi plus best four remaining externally examined subjects, graded A1=4, A2=3.5, B1=3, B2=2.5, C1=2, C2=1.5, D1=1, D2=0.5 (max 20; five A1s with 96+ exam average deemed 21) | ISC: 81 (2026 indicative entry score). ISC basis: average of the best four subjects including English
A11: AU-010 | B11: University of Sydney | C11: Australia | D11: Bachelor of Engineering (Honours) | E11: Bachelor | F11: https://www.sydney.edu.au/courses/courses/uc/bachelor-of-engineering-honours-flexible-first-year.html | G11: Go8 / Top Research | H11: English | I11: 4 | J11: ATAR equivalent 85.0. Mathematics prerequisite applies; assumed knowledge Mathematics Extension 1, Chemistry, Physics | K11: 31 (2026 indicative entry score, international; Flexible First Year stream) | L11: 14 points from best 3 A2 subjects / 14 from best 4. A-level aggregate from A2 subjects, A*=6 A=5 B=4 C=3 D=2 E=1; first figure = 3 subjects, second = 4 subjects (AS not counted) | M11: 15.5 aggregate (2026 indicative entry score). CBSE aggregate basis: English or Hindi plus best four remaining externally examined subjects, graded A1=4, A2=3.5, B1=3, B2=2.5, C1=2, C2=1.5, D1=1, D2=0.5 (max 20; five A1s with 96+ exam average deemed 21) | N11: 87 (2026 indicative entry score). ISC basis: average of the best four subjects including English | O11: Rank-based; maths prerequisite enforced | P11: IELTS: 'A minimum result of 6.5 overall and a minimum result of 6.0 in each band' | Q11: None; Mathematics prerequisite must be satisfied | R11: Semester 1 (February) intake only for this course; international direct applications close 1 December of the prior year | S11: A$60,600 international tuition fee for 2026 (first-year estimate) | T11: Vice-Chancellor's International Scholarships Scheme (merit-based, assessed from the admission application); Sydney International Student Award | U11: Australian Student visa (subclass 500) after acceptance and CoE; OSHC required; available to student visa holders (course pages state 'Available to student visa holders') | V11: Three ways: apply directly to the University (online), via an authorised agent, or via UAC - UAC is mandatory if completing an Australian Year 12 (anywhere) or the IB in Australia | W11: CRICOS 083109M (Flexible First Year). 192 credit points, Semester 1 intake only. The source sheet's generic BE(Hons) URL is dead - Sydney lists per-stream pages (Civil, Electrical, Mechanical, Software etc.); Flexible First Year page used as the generic entry route. | X11: Confirmed | Y11: Source course_url dead (404) - course split into stream pages; sheet IB 37-40 vs published 31 (FFY); sheet CBSE '90%+' wrong metric (published 15.5/20); sheet ISC 85%+ vs 87; sheet fee 50,000 vs 60,600; sheet ATAR ~95 vs 85.0; sheet deadline 15 May wrong; Semester 2 entry not offered | Z11: https://www.sydney.edu.au/courses/courses/uc/bachelor-of-engineering-honours-flexible-first-year.html | AA11: This course has a Mathematics prerequisite. [...] Assumed knowledge: Mathematics Extension 1, Chemistry, Physics; International Full Fee Paying Rate $60,600 (2026) | AB11: 13 September 2026 | AC11: yes | AD11: Pave verification, web-checked | AE11: Academic transcripts and completion certificates, English test evidence, passport; supplementary evidence via UAC where applicable | AF11: Standing university-wide closing dates published (sydney.edu.au/study/applying/application-dates.html), checked 13 September 2026; for 2027 Semester 1 that means 1 December 2026 | AG11: 2026 | AH11: A$150.00 non-refundable application processing fee (covers all applications made within one year); exemptions incl. full scholarship/sponsorship holders | AI11: 2026-12-01 | AJ11: 15.5 aggregate (2026 indicative entry score). CBSE aggregate basis: English or Hindi plus best four remaining externally examined subjects, graded A1=4, A2=3.5, B1=3, B2=2.5, C1=2, C2=1.5, D1=1, D2=0.5 (max 20; five A1s with 96+ exam average deemed 21) | ISC: 87 (2026 indicative entry score). ISC basis: average of the best four subjects including English
A12: AU-011 | B12: University of Sydney | C12: Australia | D12: Bachelor of Laws (LLB) | E12: Bachelor | F12: https://www.sydney.edu.au/courses/courses/uc/bachelor-of-arts-and-bachelor-of-laws.html | G12: Go8 / Top Research | H12: English | I12: 5 | J12: ATAR equivalent 95.5. Assumed knowledge: English Advanced | K12: 38 (2026 indicative entry score, international, BA/LLB combined) | L12: 16 points from best 3 A2 subjects / 18 from best 4. A-level aggregate from A2 subjects, A*=6 A=5 B=4 C=3 D=2 E=1; first figure = 3 subjects, second = 4 subjects (AS not counted) | M12: 18.5 aggregate (2026 indicative entry score). CBSE aggregate basis: English or Hindi plus best four remaining externally examined subjects, graded A1=4, A2=3.5, B1=3, B2=2.5, C1=2, C2=1.5, D1=1, D2=0.5 (max 20; five A1s with 96+ exam average deemed 21) | N12: 94 (2026 indicative entry score). ISC basis: average of the best four subjects including English | O12: Rank-based on combined-degree entry score; no LLB-specific test | P12: IELTS: 'A minimum result of 7.5 overall and a minimum result of 7.0 in each band' (Law combined degrees) | Q12: None (Sydney does not use an admission test for undergraduate law) | R12: International direct applications close 1 December of the year prior to commencement for Semester 1 (February) and 29 May of the commencing year for Semester 2 (August) | S12: A$56,300 international tuition fee for 2026 (first-year estimate, BA/LLB) | T12: Vice-Chancellor's International Scholarships Scheme (merit-based, assessed from the admission application); Sydney International Student Award | U12: Australian Student visa (subclass 500) after acceptance and CoE; OSHC required; available to student visa holders (course pages state 'Available to student visa holders') | V12: Three ways: apply directly to the University (online), via an authorised agent, or via UAC - UAC is mandatory if completing an Australian Year 12 (anywhere) or the IB in Australia | W12: CRICOS 006441D (BA/LLB). Intakes: Semester 1 (February) and Semester 2 (August). Sydney does NOT offer a standalone 4-year undergraduate LLB - undergraduate law is a 5-year combined degree (Arts/Commerce/Science/etc. + LLB); BA/LLB used as reference combination. | X12: Confirmed | Y12: Sheet describes a 4-year direct-entry LLB that does not exist (dead URL; undergraduate law is 5-year combined only); sheet IB 41-45 vs published 38; sheet IELTS 7.0/6.5 vs published 7.5 overall/7.0 bands; sheet fee 52,000 vs 56,300; sheet CBSE 95%+ wrong metric (18.5/20); sheet ISC 92%+ vs 94 | Z12: https://www.sydney.edu.au/courses/courses/uc/bachelor-of-arts-and-bachelor-of-laws.html | AA12: IELTS score: A minimum result of 7.5 overall and a minimum result of 7.0 in each band; DURATION 5 years full-time | AB12: 13 September 2026 | AC12: yes | AD12: Pave verification, web-checked | AE12: Academic transcripts and completion certificates, English test evidence, passport; supplementary evidence via UAC where applicable | AF12: Standing university-wide closing dates published (sydney.edu.au/study/applying/application-dates.html), checked 13 September 2026; for 2027 Semester 1 that means 1 December 2026 | AG12: 2026 | AH12: A$150.00 non-refundable application processing fee (covers all applications made within one year); exemptions incl. full scholarship/sponsorship holders | AI12: 2026-12-01 | AJ12: 18.5 aggregate (2026 indicative entry score). CBSE aggregate basis: English or Hindi plus best four remaining externally examined subjects, graded A1=4, A2=3.5, B1=3, B2=2.5, C1=2, C2=1.5, D1=1, D2=0.5 (max 20; five A1s with 96+ exam average deemed 21) | ISC: 94 (2026 indicative entry score). ISC basis: average of the best four subjects including English
A13: AU-012 | B13: University of Sydney | C13: Australia | D13: Bachelor of Psychology (Honours) | E13: Bachelor | F13: https://www.sydney.edu.au/courses/courses/uc/bachelor-of-psychology-honours.html | G13: Go8 / Top Research | H13: English | I13: 4 | J13: ATAR equivalent 91.0. Assumed knowledge: Mathematics Advanced | K13: 34 (2026 indicative entry score, international) | L13: 15 points from best 3 A2 subjects / 16 from best 4. A-level aggregate from A2 subjects, A*=6 A=5 B=4 C=3 D=2 E=1; first figure = 3 subjects, second = 4 subjects (AS not counted) | M13: 17.5 aggregate (2026 indicative entry score). CBSE aggregate basis: English or Hindi plus best four remaining externally examined subjects, graded A1=4, A2=3.5, B1=3, B2=2.5, C1=2, C2=1.5, D1=1, D2=0.5 (max 20; five A1s with 96+ exam average deemed 21) | N13: 91 (2026 indicative entry score). ISC basis: average of the best four subjects including English | O13: Rank-based admission on qualification entry score | P13: IELTS: 'A minimum result of 6.5 overall and a minimum result of 6.0 in each band' | Q13: None | R13: Semester 1 (February) intake only for this course; international direct applications close 1 December of the prior year | S13: A$60,600 international tuition fee for 2026 (first-year estimate) | T13: Vice-Chancellor's International Scholarships Scheme (merit-based, assessed from the admission application); Sydney International Student Award | U13: Australian Student visa (subclass 500) after acceptance and CoE; OSHC required; available to student visa holders (course pages state 'Available to student visa holders') | V13: Three ways: apply directly to the University (online), via an authorised agent, or via UAC - UAC is mandatory if completing an Australian Year 12 (anywhere) or the IB in Australia | W13: CRICOS 107970E. 192 credit points; APAC-accredited pathway to psychologist registration. Note a separate 3-year Bachelor of Psychology (CRICOS 107969J) also exists. | X13: Confirmed | Y13: Sheet fee 49,000 vs published 60,600; sheet CBSE '88%+' wrong metric (published 17.5/20); sheet ISC 80%+ vs 91; sheet deadline 15 May wrong; Semester 2 entry not offered; sheet IB lower bound 34 matches published 34 | Z13: https://www.sydney.edu.au/courses/courses/uc/bachelor-of-psychology-honours.html | AA13: IELTS score: A minimum result of 6.5 overall and a minimum result of 6.0 in each band; International Full Fee Paying Rate $60,600 (2026) | AB13: 13 September 2026 | AC13: yes | AD13: Pave verification, web-checked | AE13: Academic transcripts and completion certificates, English test evidence, passport; supplementary evidence via UAC where applicable | AF13: Standing university-wide closing dates published (sydney.edu.au/study/applying/application-dates.html), checked 13 September 2026; for 2027 Semester 1 that means 1 December 2026 | AG13: 2026 | AH13: A$150.00 non-refundable application processing fee (covers all applications made within one year); exemptions incl. full scholarship/sponsorship holders | AI13: 2026-12-01 | AJ13: 17.5 aggregate (2026 indicative entry score). CBSE aggregate basis: English or Hindi plus best four remaining externally examined subjects, graded A1=4, A2=3.5, B1=3, B2=2.5, C1=2, C2=1.5, D1=1, D2=0.5 (max 20; five A1s with 96+ exam average deemed 21) | ISC: 91 (2026 indicative entry score). ISC basis: average of the best four subjects including English
A14: AU-013 | B14: UNSW Sydney | C14: Australia | D14: Bachelor of Commerce | E14: Bachelor | F14: https://www.unsw.edu.au/study/undergraduate/bachelor-of-commerce | G14: Go8 / Top Research | H14: English | I14: 3 | J14: India State Board 98.0 (Maharashtra, Karnataka, Tamil Nadu only); SAT 1300 (with completed senior secondary) | K14: 36.0 international direct entry requirement (2026); for context the domestic 2026 lowest selection rank was 97.0 (IB guide 41.0) | L14: 15.0 points international direct entry (2026). A-level basis: minimum two A2 subjects; score aggregated from best 2-4 A2 subjects, A*=6 A=5 B=4 C=3 D=2 E=1 | M14: 85.0 (2026 international direct entry). CBSE basis: average percentage across English or Hindi plus best four remaining subjects (range marks use mid-point) | N14: 92.0 (2026 international direct entry, Indian School Certificate CISCE) | O14: Rank/score-based; International Admissions Diversity Pathway can add 5 points to International ATAR for eligible applicants | P14: IELTS 7.0 overall (min 6.0 in each subtest) - UNSW Business School requirement (standard UNSW UG is 6.5/6.0) | Q14: None. Assumed knowledge: Mathematics Advanced | R14: Rolling offer rounds. Published Term 1 2027 undergraduate international round deadlines: 14 May 2026, 16 July 2026, 20 August 2026, 24 September 2026 (completed-application deadlines per round); later rounds published progressively | S14: A$56,500 indicative first year fee 2026 (indicative full fee to complete degree $180,500) | T14: International Scientia Coursework Scholarship (full tuition or $20,000/year); UNSW International Student Award (20% tuition contribution, 500-word personal statement) | U14: Australian Student visa (subclass 500) after acceptance and CoE; OSHC required | V14: Direct via the UNSW Applicant Portal, via an authorised agent, or via UAC (UAC required if completing an Australian Year 12; IB students in Australia may use UAC or apply direct) | W14: CRICOS 001919M. Program 3502, UAC 424000. Commencing Terms 1, 2 & 3 (Feb/May/Sep). 16 majors. | X14: Confirmed | Y14: Sheet IELTS 6.5/6.0 vs published Business School 7.0 overall/6.0; sheet CBSE 90%+ vs published 85.0; sheet ISC 85%+ vs 92.0; sheet fee 56,500 matches; sheet deadline '14 May' is only round 1 of the 2027 offer rounds | Z14: https://www.unsw.edu.au/study/undergraduate/bachelor-of-commerce | AA14: All India Senior School Certificate (CBSE) 85.0; Indian School Certificate (CISCE) 92.0; International Baccalaureate Diploma (IB) 36.0; 2026 Indicative First Year Fee $56,500* | AB14: 13 September 2026 | AC14: yes | AD14: Pave verification, web-checked | AE14: Academic transcripts/certificates, English evidence, passport; personal statement for some scholarships; submit via UNSW Applicant Portal | AF14: UNSW publishes per-round offer schedules rather than a single closing date (unsw.edu.au/study/international-students/admissions-info, checked 13 September 2026); final T1 2027 round not yet listed, so deadline_iso_close left blank | AG14: 2026 | AH14: A non-refundable application fee of $150 AUD may be payable via the UNSW Applicant Portal (credit card; some exclusions) | AJ14: 85.0 (2026 international direct entry). CBSE basis: average percentage across English or Hindi plus best four remaining subjects (range marks use mid-point) | ISC: 92.0 (2026 international direct entry, Indian School Certificate CISCE)
A15: AU-014 | B15: UNSW Sydney | C15: Australia | D15: Bachelor of Engineering (Honours) | E15: Bachelor | F15: https://www.unsw.edu.au/study/undergraduate/bachelor-of-engineering-honours | G15: Go8 / Top Research | H15: English | I15: 4 | J15: India State Board 96.0 (MH/KA/TN only); SAT 1260 | K15: 35.0 international direct entry requirement (2026) | L15: 13.0 points international direct entry (2026). A-level basis: minimum two A2 subjects; score aggregated from best 2-4 A2 subjects, A*=6 A=5 B=4 C=3 D=2 E=1 | M15: 81.0 (2026 international direct entry). CBSE basis: average percentage across English or Hindi plus best four remaining subjects (range marks use mid-point) | N15: 90.0 (2026 international direct entry) | O15: Rank/score-based; flexible-entry then specialisation into streams (Civil, Mechanical, Electrical, Software, Chemical, Mining etc.) | P15: IELTS 6.5 overall (min 6.0 in each subtest) - standard UNSW requirement | Q15: None. Assumed knowledge: Mathematics Extension 1, Physics | R15: Rolling offer rounds. Published Term 1 2027 undergraduate international round deadlines: 14 May 2026, 16 July 2026, 20 August 2026, 24 September 2026 (completed-application deadlines per round); later rounds published progressively | S15: A$61,500 indicative first year fee 2026 | T15: International Scientia Coursework Scholarship (full tuition or $20,000/year); UNSW International Student Award (20% tuition contribution, 500-word personal statement) | U15: Australian Student visa (subclass 500) after acceptance and CoE; OSHC required | V15: Direct via the UNSW Applicant Portal, via an authorised agent, or via UAC (UAC required if completing an Australian Year 12; IB students in Australia may use UAC or apply direct) | W15: CRICOS 056835E. UAC 425000. Commencing Terms 1, 2 & 3. | X15: Confirmed | Y15: Sheet IB 38-42 vs published international direct entry 35.0; sheet CBSE 92%+ vs 81.0; sheet ISC 88%+ vs 90.0; sheet fee 58,000 vs 61,500; sheet deadline 14 May is only an offer-round date | Z15: https://www.unsw.edu.au/study/undergraduate/bachelor-of-engineering-honours | AA15: All India Senior School Certificate (CBSE) 81.0; International Baccalaureate Diploma (IB) 35.0; 2026 Indicative First Year Fee $61,500* | AB15: 13 September 2026 | AC15: yes | AD15: Pave verification, web-checked | AE15: Academic transcripts/certificates, English evidence, passport; personal statement for some scholarships; submit via UNSW Applicant Portal | AF15: UNSW publishes per-round offer schedules rather than a single closing date (unsw.edu.au/study/international-students/admissions-info, checked 13 September 2026); final T1 2027 round not yet listed, so deadline_iso_close left blank | AG15: 2026 | AH15: A non-refundable application fee of $150 AUD may be payable via the UNSW Applicant Portal (credit card; some exclusions) | AJ15: 81.0 (2026 international direct entry). CBSE basis: average percentage across English or Hindi plus best four remaining subjects (range marks use mid-point) | ISC: 90.0 (2026 international direct entry)
A16: AU-015 | B16: UNSW Sydney | C16: Australia | D16: Bachelor of Computer Science | E16: Bachelor | F16: https://www.unsw.edu.au/study/undergraduate/bachelor-of-computer-science | G16: Go8 / Top Research | H16: English | I16: 3 | J16: India State Board 95.0 (MH/KA/TN only) | K16: 34.0 international direct entry requirement (2026); domestic 2026 LSR 93.0 (IB guide 37.0) | L16: 12.0 points international direct entry (2026). A-level basis: minimum two A2 subjects; score aggregated from best 2-4 A2 subjects, A*=6 A=5 B=4 C=3 D=2 E=1 | M16: 81.0 (2026 international direct entry). CBSE basis: average percentage across English or Hindi plus best four remaining subjects (range marks use mid-point) | N16: 89.0 (2026 international direct entry) | O16: Rank/score-based | P16: IELTS 6.5 overall (min 6.0 in each subtest) - standard UNSW requirement | Q16: None. Assumed knowledge: Mathematics Extension 1 | R16: Rolling offer rounds. Published Term 1 2027 undergraduate international round deadlines: 14 May 2026, 16 July 2026, 20 August 2026, 24 September 2026 (completed-application deadlines per round); later rounds published progressively | S16: A$61,000 indicative first year fee 2026 | T16: International Scientia Coursework Scholarship (full tuition or $20,000/year); UNSW International Student Award (20% tuition contribution, 500-word personal statement) | U16: Australian Student visa (subclass 500) after acceptance and CoE; OSHC required | V16: Direct via the UNSW Applicant Portal, via an authorised agent, or via UAC (UAC required if completing an Australian Year 12; IB students in Australia may use UAC or apply direct) | W16: CRICOS 015784F. Official degree title on the page is 'Bachelor of Science (Computer Science)', program 3778, UAC 425800. Commencing Terms 1, 2 & 3. (UNSW's separate flagship Bachelor of Computer Science program 3778 page carries this title.) | X16: Confirmed | Y16: Sheet IB 37-40 vs published international direct entry 34.0 (37 is the domestic LSR-derived guide); sheet CBSE 90%+ vs 81.0; sheet ISC 85%+ vs 89.0; sheet fee 56,000 vs 61,000; page titles the degree 'Bachelor of Science (Computer Science)' | Z16: https://www.unsw.edu.au/study/undergraduate/bachelor-of-computer-science | AA16: All India Senior School Certificate (CBSE) 81.0; International Baccalaureate Diploma (IB) 34.0; 2026 Indicative First Year Fee $61,000* | AB16: 13 September 2026 | AC16: yes | AD16: Pave verification, web-checked | AE16: Academic transcripts/certificates, English evidence, passport; personal statement for some scholarships; submit via UNSW Applicant Portal | AF16: UNSW publishes per-round offer schedules rather than a single closing date (unsw.edu.au/study/international-students/admissions-info, checked 13 September 2026); final T1 2027 round not yet listed, so deadline_iso_close left blank | AG16: 2026 | AH16: A non-refundable application fee of $150 AUD may be payable via the UNSW Applicant Portal (credit card; some exclusions) | AJ16: 81.0 (2026 international direct entry). CBSE basis: average percentage across English or Hindi plus best four remaining subjects (range marks use mid-point) | ISC: 89.0 (2026 international direct entry)
